Workbook

Sheet Verpleegkundigen
A1: Naam | B1: Max patiënten per dag | C1: naam_clean (niet aanpassen) | H1: Let op!
A2: Merel | B2: 10 | C2: =IF(A2="","",LOWER(SUBSTITUTE(SUBSTITUTE(A2," ",""),CHAR(160),""))) -> merel | H2: Bij verandering van het max aantal patiënten van een verpleegkundige eerst de formules weghalen in de dagen die al geweest zijn. Dit kan je doen door simpel de rijen bij (max capaciteit) en (max aantal patiënten afgesproken) te kopiëren en meteen weer te plakken. Wanneer je ziet dat er geen formules meer staan in die cellen maar alleen de aantallen kan je hier de verandering maken in max patiënten per dag.
A3: Joyce | B3: 10 | C3: =IF(A3="","",LOWER(SUBSTITUTE(SUBSTITUTE(A3," ",""),CHAR(160),""))) -> joyce
A4: Suzan | B4: 10 | C4: =IF(A4="","",LOWER(SUBSTITUTE(SUBSTITUTE(A4," ",""),CHAR(160),""))) -> suzan
A5: Carla | B5: 10 | C5: =IF(A5="","",LOWER(SUBSTITUTE(SUBSTITUTE(A5," ",""),CHAR(160),""))) -> carla
A6: Sanne | B6: 10 | C6: =IF(A6="","",LOWER(SUBSTITUTE(SUBSTITUTE(A6," ",""),CHAR(160),""))) -> sanne
A7: Henriette | B7: 10 | C7: =IF(A7="","",LOWER(SUBSTITUTE(SUBSTITUTE(A7," ",""),CHAR(160),""))) -> henriette
A8: Emmy | B8: 10 | C8: =IF(A8="","",LOWER(SUBSTITUTE(SUBSTITUTE(A8," ",""),CHAR(160),""))) -> emmy
A9: Yvonne | B9: 10 | C9: =IF(A9="","",LOWER(SUBSTITUTE(SUBSTITUTE(A9," ",""),CHAR(160),""))) -> yvonne
A10: Sarina | B10: 5 | C10: =IF(A10="","",LOWER(SUBSTITUTE(SUBSTITUTE(A10," ",""),CHAR(160),""))) -> sarina
A11: Irma | B11: 10 | C11: =IF(A11="","",LOWER(SUBSTITUTE(SUBSTITUTE(A11," ",""),CHAR(160),""))) -> irma
A12: Lisa | B12: 6 | C12: =IF(A12="","",LOWER(SUBSTITUTE(SUBSTITUTE(A12," ",""),CHAR(160),""))) -> lisa
A13: Ailien | B13: 3 | C13: =IF(A13="","",LOWER(SUBSTITUTE(SUBSTITUTE(A13," ",""),CHAR(160),""))) -> ailien
C14: =IF(A14="","",LOWER(SUBSTITUTE(SUBSTITUTE(A14," ",""),CHAR(160),"")))
C15: =IF(A15="","",LOWER(SUBSTITUTE(SUBSTITUTE(A15," ",""),CHAR(160),"")))
C16: =IF(A16="","",LOWER(SUBSTITUTE(SUBSTITUTE(A16," ",""),CHAR(160),"")))
C17: =IF(A17="","",LOWER(SUBSTITUTE(SUBSTITUTE(A17," ",""),CHAR(160),"")))
C18: =IF(A18="","",LOWER(SUBSTITUTE(SUBSTITUTE(A18," ",""),CHAR(160),"")))
C19: =IF(A19="","",LOWER(SUBSTITUTE(SUBSTITUTE(A19," ",""),CHAR(160),"")))
C20: =IF(A20="","",LOWER(SUBSTITUTE(SUBSTITUTE(A20," ",""),CHAR(160),"")))
C21: =IF(A21="","",LOWER(SUBSTITUTE(SUBSTITUTE(A21," ",""),CHAR(160),"")))
C22: =IF(A22="","",LOWER(SUBSTITUTE(SUBSTITUTE(A22," ",""),CHAR(160),"")))
C23: =IF(A23="","",LOWER(SUBSTITUTE(SUBSTITUTE(A23," ",""),CHAR(160),"")))
C24: =IF(A24="","",LOWER(SUBSTITUTE(SUBSTITUTE(A24," ",""),CHAR(160),"")))
C25: =IF(A25="","",LOWER(SUBSTITUTE(SUBSTITUTE(A25," ",""),CHAR(160),"")))
... C101: =IF(A101="","",LOWER(SUBSTITUTE(SUBSTITUTE(A101," ",""),CHAR(160),"")))

Sheet Instructies
A1: Rollen: Teamhoofd: Vult de verpleegkundige en dagco in, geeft bij opmerkingen senna aan wanneer ze een verandering heeft gedaan en wat voor verandering, zet het max aantal patienten afgesproken neer of zet dit in haar opmerkingen. planners: zetten belangrijke opmerkingen en vullen het aantal patiënten in. Werking van het Excel bestand: Dit is excel bestand is bedoeld voor de planners en het teamhoofd om een inzicht te hebben in de capaciteit op de afdeling D4B. De volgende dingen zijn er in te zien: - De bezetting van verpleegkundige per dag - Het aantal patiënten wat ingepland kan en mag worden - Het aantal patiënten wat ingepland is op elke dag Aan de hand van deze gegevens word automatisch berekend en gevisualiseerd of het aantal patiënten matched aan de capaciteit op een dag, hoeveel overschrijding er is, of de maximale capaciteit hoger licht dan de afgesproken capaciteit en hoeveel capaciteit er is volgens de afspraken van aantal patiënten per verpleegkundige. Hoe moet je het gebruiken: 1. Check of alle verpleegkudige staan in de tab "verpleegkundige" en of zij een waarde hebben gekregen van het aantal patiënten waarvoor zij geteld mogen worden. Als een verpleegkundige of invaller er nog niet instaan kan deze simpel worden toegevoegt door de naam erbij te zetten onder de andere namen en een waarde te geven. Vul vervolgens ook de naam in bij de kolom naam_clean ZONDER HOOFDLETTER 2. Vul de namen in van de verpleegkundige in de kolom "naam verpleegkundige" op de gewenste dag in een een tab met de juiste maand. De namen kunnen ingevoerd worden met of zonder hoofdletter. Let wel goed op het gebruik van de komma's houd het volgende lay-out aan [Naam, Naam, Naam, Naam]. Let goed op voor spelfouten en gebruik geen dubbele spatie na de komma. 3. Vul de Dagco in door de naam te typen zonder enige toevoegingen. 4. Pas handmatig het "Aantal patienten afgesproken" in wanneer gewenst is dat dit afwijkt van de automatische berekende "Max Capaciteit" (de overschreidingen en kleur bij aantal patiënten is gebasseerd op de kolom "Aantal patiënten afgesproken" 5. Vul in het aantal ingeplande patiënten onder de kolom "Aantal patiënten" Lees hieronder hoe je extra tabs voor extra maanden kan toevoegen
A40: Klik met de linker muisknop op de tabblad van de maand die je wil kopiëren. Kies verplaatsen of kopiëren… selecteer het tabblad wat je wil kopiëren en vink onderaan aan kopie maken. Je zal dan de gekopiërde tabblad zien met (2) er achter. Verander Deze naam daar de gewenste naam door te dubbel klikken op het tabblad. Sleep het tabblad naar de juiste positie onderaan. Pas de datums aan en voeg extra rijen toe wanneer nodig. Hieronder is zijn de formules te kopieren in de cel die je direct kan plakken en vervolgens zouden ze moeten werken. Het beste is om een rij toe te voegen waar je wilt en vervolgens een andere rij te kopiëren en daar te plakken. Vervolgens pas je alleen dingen aan als de datum. Extra aanpassingen: Wil je veranderen hoeveel patiënten een dagco mag hebben 2-12-2025 is het maar (1) dan kan je dit doen in de formule die in de cellen staan in de kollomen "Aantal patienten afgesproken" en "Max Capaciteit" Voorbeeld: =ALS(EN($J8="";$K8="");"";SOMPRODUCT(--ISGETAL(VIND.SPEC(","&Verpleegkundigen!$C$2:$C$100&",";","&KLEINE.LETTERS(SUBSTITUEREN(SUBSTITUEREN($J8;" ";"");TEKEN(160);""))&","))*(Verpleegkundigen!$C$2:$C$100<>KLEINE.LETTERS(SUBSTITUEREN(SUBSTITUEREN($K8;" ";"");TEKEN(160);"")));Verpleegkundigen!$B$2:$B$100)+ALS($K8<>"";1;0)) Verander de rood gekleurde 1 naar het nieuwe aantal wat de dagco mag hebben.

Sheet Nov '25
A1: Datum | B1: Weekdag | C1: Aantal patiënten | D1: Max aantal patiënten | E1: Overschrijding | F1: Opmerking | G1: Aantal vpk | H1: Naam verpleegkundige | I1: Dagco (naam)
A2: Week 45
A3: 45964 | B3: ma | C3: 28 | D3: =IF(AND($H3="",$I3=""),"",SUMPRODUCT(--ISNUMBER(SEARCH(","&Verpleegkundigen!$C$2:$C$100&",",","&LOWER(SUBSTITUTE(SUBSTITUTE($H3," ",""),CHAR(160),""))&","))*(Verpleegkundigen!$C$2:$C$100<>LOWER(SUBSTITUTE(SUBSTITUTE($I3," ",""),CHAR(160),""))),Verpleegkundigen!$B$2:$B$100)+IF($I3<>"",1,0)) | E3: =IF(AND(C3<>"",D3<>"",C3>D3),"+" & TEXT(C3-D3,"0"),"") | F3: 29 ivm yvonne 8 pt | G3: =IF($H3="",4,LEN($H3)-LEN(SUBSTITUTE($H3,",",""))+1) -> 4
A4: 45965 | B4: di | C4: 26 | D4: =IF(AND($H4="",$I4=""),"",SUMPRODUCT(--ISNUMBER(SEARCH(","&Verpleegkundigen!$C$2:$C$100&",",","&LOWER(SUBSTITUTE(SUBSTITUTE($H4," ",""),CHAR(160),""))&","))*(Verpleegkundigen!$C$2:$C$100<>LOWER(SUBSTITUTE(SUBSTITUTE($I4," ",""),CHAR(160),""))),Verpleegkundigen!$B$2:$B$100)+IF($I4<>"",1,0)) | E4: =IF(AND(C4<>"",D4<>"",C4>D4),"+" & TEXT(C4-D4,"0"),"") | F4: er is een flexals 4de dus 25 | G4: =IF($H4="",3,LEN($H4)-LEN(SUBSTITUTE($H4,",",""))+1) -> 3
A5: 45966 | B5: wo | C5: 19 | D5: =IF(AND($H5="",$I5=""),"",SUMPRODUCT(--ISNUMBER(SEARCH(","&Verpleegkundigen!$C$2:$C$100&",",","&LOWER(SUBSTITUTE(SUBSTITUTE($H5," ",""),CHAR(160),""))&","))*(Verpleegkundigen!$C$2:$C$100<>LOWER(SUBSTITUTE(SUBSTITUTE($I5," ",""),CHAR(160),""))),Verpleegkundigen!$B$2:$B$100)+IF($I5<>"",1,0)) | E5: =IF(AND(C5<>"",D5<>"",C5>D5),"+" & TEXT(C5-D5,"0"),"") | F5: 1 dubbele Er is een flexer 6patienten naar 5A | G5: =IF($H5="",3,LEN($H5)-LEN(SUBSTITUTE($H5,",",""))+1) -> 3
A6: 45967 | B6: do | C6: 25 | D6: =IF(AND($H6="",$I6=""),"",SUMPRODUCT(--ISNUMBER(SEARCH(","&Verpleegkundigen!$C$2:$C$100&",",","&LOWER(SUBSTITUTE(SUBSTITUTE($H6," ",""),CHAR(160),""))&","))*(Verpleegkundigen!$C$2:$C$100<>LOWER(SUBSTITUTE(SUBSTITUTE($I6," ",""),CHAR(160),""))),Verpleegkundigen!$B$2:$B$100)+IF($I6<>"",1,0)) | E6: =IF(AND(C6<>"",D6<>"",C6>D6),"+" & TEXT(C6-D6,"0"),"") | F6: en Sarina dus 24 is goed | G6: =IF($H6="",3,LEN($H6)-LEN(SUBSTITUTE($H6,",",""))+1) -> 3
A7: 45968 | B7: vr | C7: 21 | D7: =IF(AND($H7="",$I7=""),"",SUMPRODUCT(--ISNUMBER(SEARCH(","&Verpleegkundigen!$C$2:$C$100&",",","&LOWER(SUBSTITUTE(SUBSTITUTE($H7," ",""),CHAR(160),""))&","))*(Verpleegkundigen!$C$2:$C$100<>LOWER(SUBSTITUTE(SUBSTITUTE($I7," ",""),CHAR(160),""))),Verpleegkundigen!$B$2:$B$100)+IF($I7<>"",1,0)) | E7: =IF(AND(C7<>"",D7<>"",C7>D7),"+" & TEXT(C7-D7,"0"),"") | F7: 1 dubbele | G7: =IF($H7="",3,LEN($H7)-LEN(SUBSTITUTE($H7,",",""))+1) -> 3
A8: Week 46
A9: 45971 | B9: ma | C9: 26 | D9: =IF(AND($H9="",$I9=""),"",SUMPRODUCT(--ISNUMBER(SEARCH(","&Verpleegkundigen!$C$2:$C$100&",",","&LOWER(SUBSTITUTE(SUBSTITUTE($H9," ",""),CHAR(160),""))&","))*(Verpleegkundigen!$C$2:$C$100<>LOWER(SUBSTITUTE(SUBSTITUTE($I9," ",""),CHAR(160),""))),Verpleegkundigen!$B$2:$B$100)+IF($I9<>"",1,0)) | E9: =IF(AND(C9<>"",D9<>"",C9>D9),"+" & TEXT(C9-D9,"0"),"") | F9: Sarina is er yvonne tot 14;00 en flex | G9: =IF($H9="",3,LEN($H9)-LEN(SUBSTITUTE($H9,",",""))+1) -> 3
A10: 45972 | B10: di | C10: 32 | D10: =IF(AND($H10="",$I10=""),"",SUMPRODUCT(--ISNUMBER(SEARCH(","&Verpleegkundigen!$C$2:$C$100&",",","&LOWER(SUBSTITUTE(SUBSTITUTE($H10," ",""),CHAR(160),""))&","))*(Verpleegkundigen!$C$2:$C$100<>LOWER(SUBSTITUTE(SUBSTITUTE($I10," ",""),CHAR(160),""))),Verpleegkundigen!$B$2:$B$100)+IF($I10<>"",1,0)) | E10: =IF(AND(C10<>"",D10<>"",C10>D10),"+" & TEXT(C10-D10,"0"),"") | G10: =IF($H10="",4,LEN($H10)-LEN(SUBSTITUTE($H10,",",""))+1) -> 4
A11: 45973 | B11: wo | C11: 24 | D11: =IF(AND($H11="",$I11=""),"",SUMPRODUCT(--ISNUMBER(SEARCH(","&Verpleegkundigen!$C$2:$C$100&",",","&LOWER(SUBSTITUTE(SUBSTITUTE($H11," ",""),CHAR(160),""))&","))*(Verpleegkundigen!$C$2:$C$100<>LOWER(SUBSTITUTE(SUBSTITUTE($I11," ",""),CHAR(160),""))),Verpleegkundigen!$B$2:$B$100)+IF($I11<>"",1,0)) | E11: =IF(AND(C11<>"",D11<>"",C11>D11),"+" & TEXT(C11-D11,"0"),"") | F11: 1 dubbele / houden op 25 max, indien geen flex dan 21 | G11: =IF($H11="",3,LEN($H11)-LEN(SUBSTITUTE($H11,",",""))+1) -> 3
A12: 45974 | B12: do | C12: 30 | D12: =IF(AND($H12="",$I12=""),"",SUMPRODUCT(--ISNUMBER(SEARCH(","&Verpleegkundigen!$C$2:$C$100&",",","&LOWER(SUBSTITUTE(SUBSTITUTE($H12," ",""),CHAR(160),""))&","))*(Verpleegkundigen!$C$2:$C$100<>LOWER(SUBSTITUTE(SUBSTITUTE($I12," ",""),CHAR(160),""))),Verpleegkundigen!$B$2:$B$100)+IF($I12<>"",1,0)) | E12: =IF(AND(C12<>"",D12<>"",C12>D12),"+" & TEXT(C12-D12,"0"),"") | F12: NIET MEER BIJPLANNEN INDIEN UITVALLER | G12: =IF($H12="",4,LEN($H12)-LEN(SUBSTITUTE($H12,",",""))+1) -> 4
A13: 45975 | B13: vr | C13: 25 | D13: =IF(AND($H13="",$I13=""),"",SUMPRODUCT(--ISNUMBER(SEARCH(","&Verpleegkundigen!$C$2:$C$100&",",","&LOWER(SUBSTITUTE(SUBSTITUTE($H13," ",""),CHAR(160),""))&","))*(Verpleegkundigen!$C$2:$C$100<>LOWER(SUBSTITUTE(SUBSTITUTE($I13," ",""),CHAR(160),""))),Verpleegkundigen!$B$2:$B$100)+IF($I13<>"",1,0)) | E13: =IF(AND(C13<>"",D13<>"",C13>D13),"+" & TEXT(C13-D13,"0"),"") | F13: houden op 23 max, indien geen flex dan 5A ? | G13: =IF($H13="",3,LEN($H13)-LEN(SUBSTITUTE($H13,",",""))+1) -> 3
A14: Week 47
A15: 45978 | B15: ma | C15: 33 | D15: =IF(AND($H15="",$I15=""),"",SUMPRODUCT(--ISNUMBER(SEARCH(","&Verpleegkundigen!$C$2:$C$100&",",","&LOWER(SUBSTITUTE(SUBSTITUTE($H15," ",""),CHAR(160),""))&","))*(Verpleegkundigen!$C$2:$C$100<>LOWER(SUBSTITUTE(SUBSTITUTE($I15," ",""),CHAR(160),""))),Verpleegkundigen!$B$2:$B$100)+IF($I15<>"",1,0)) | E15: =IF(AND(C15<>"",D15<>"",C15>D15),"+" & TEXT(C15-D15,"0"),"") | F15: Sarina is er yvonne tot 14;00 | G15: =IF($H15="",4,LEN($H15)-LEN(SUBSTITUTE($H15,",",""))+1) -> 4
A16: 45979 | B16: di | C16: 30 | D16: =IF(AND($H16="",$I16=""),"",SUMPRODUCT(--ISNUMBER(SEARCH(","&Verpleegkundigen!$C$2:$C$100&",",","&LOWER(SUBSTITUTE(SUBSTITUTE($H16," ",""),CHAR(160),""))&","))*(Verpleegkundigen!$C$2:$C$100<>LOWER(SUBSTITUTE(SUBSTITUTE($I16," ",""),CHAR(160),""))),Verpleegkundigen!$B$2:$B$100)+IF($I16<>"",1,0)) | E16: =IF(AND(C16<>"",D16<>"",C16>D16),"+" & TEXT(C16-D16,"0"),"") | F16: Niets meer bij plannen gaat iemand af komt misschien flexer | G16: =IF($H16="",4,LEN($H16)-LEN(SUBSTITUTE($H16,",",""))+1) -> 4
A17: 45980 | B17: wo | C17: 24 | D17: =IF(AND($H17="",$I17=""),"",SUMPRODUCT(--ISNUMBER(SEARCH(","&Verpleegkundigen!$C$2:$C$100&",",","&LOWER(SUBSTITUTE(SUBSTITUTE($H17," ",""),CHAR(160),""))&","))*(Verpleegkundigen!$C$2:$C$100<>LOWER(SUBSTITUTE(SUBSTITUTE($I17," ",""),CHAR(160),""))),Verpleegkundigen!$B$2:$B$100)+IF($I17<>"",1,0)) | E17: =IF(AND(C17<>"",D17<>"",C17>D17),"+" & TEXT(C17-D17,"0"),"") | F17: 2 dubbele / houden op 25 max, indien geen flex 5A | G17: =IF($H17="",3,LEN($H17)-LEN(SUBSTITUTE($H17,",",""))+1) -> 3
A18: 45981 | B18: do | C18: 29 | D18: =IF(AND($H18="",$I18=""),"",SUMPRODUCT(--ISNUMBER(SEARCH(","&Verpleegkundigen!$C$2:$C$100&",",","&LOWER(SUBSTITUTE(SUBSTITUTE($H18," ",""),CHAR(160),""))&","))*(Verpleegkundigen!$C$2:$C$100<>LOWER(SUBSTITUTE(SUBSTITUTE($I18," ",""),CHAR(160),""))),Verpleegkundigen!$B$2:$B$100)+IF($I18<>"",1,0)) | E18: =IF(AND(C18<>"",D18<>"",C18>D18),"+" & TEXT(C18-D18,"0"),"") | F18: yvonne tot 14:00 | G18: =IF($H18="",4,LEN($H18)-LEN(SUBSTITUTE($H18,",",""))+1) -> 4
A19: 45982 | B19: vr | C19: 25 | D19: =IF(AND($H19="",$I19=""),"",SUMPRODUCT(--ISNUMBER(SEARCH(","&Verpleegkundigen!$C$2:$C$100&",",","&LOWER(SUBSTITUTE(SUBSTITUTE($H19," ",""),CHAR(160),""))&","))*(Verpleegkundigen!$C$2:$C$100<>LOWER(SUBSTITUTE(SUBSTITUTE($I19," ",""),CHAR(160),""))),Verpleegkundigen!$B$2:$B$100)+IF($I19<>"",1,0)) | E19: =IF(AND(C19<>"",D19<>"",C19>D19),"+" & TEXT(C19-D19,"0"),"") | F19: houden op 25 max, (collega op kantoor) niet meer bij plannen | G19: =IF($H19="",3,LEN($H19)-LEN(SUBSTITUTE($H19,",",""))+1) -> 3
A20: Week 48
A21: 45985 | B21: ma | C21: 31 | D21: =IF(AND($H21="",$I21=""),"",SUMPRODUCT(--ISNUMBER(SEARCH(","&Verpleegkundigen!$C$2:$C$100&",",","&LOWER(SUBSTITUTE(SUBSTITUTE($H21," ",""),CHAR(160),""))&","))*(Verpleegkundigen!$C$2:$C$100<>LOWER(SUBSTITUTE(SUBSTITUTE($I21," ",""),CHAR(160),""))),Verpleegkundigen!$B$2:$B$100)+IF($I21<>"",1,0)) | E21: =IF(AND(C21<>"",D21<>"",C21>D21),"+" & TEXT(C21-D21,"0"),"") | F21: Irma 4e, Yvonne tot 14u | G21: =IF($H21="",4,LEN($H21)-LEN(SUBSTITUTE($H21,",",""))+1) -> 4
A22: 45986 | B22: di | C22: 24 | D22: =IF(AND($H22="",$I22=""),"",SUMPRODUCT(--ISNUMBER(SEARCH(","&Verpleegkundigen!$C$2:$C$100&",",","&LOWER(SUBSTITUTE(SUBSTITUTE($H22," ",""),CHAR(160),""))&","))*(Verpleegkundigen!$C$2:$C$100<>LOWER(SUBSTITUTE(SUBSTITUTE($I22," ",""),CHAR(160),""))),Verpleegkundigen!$B$2:$B$100)+IF($I22<>"",1,0)) | E22: =IF(AND(C22<>"",D22<>"",C22>D22),"+" & TEXT(C22-D22,"0"),"") | F22: Henriette vanaf 15;30 uur alleen | Yvonne tot 15,30, Merel tot 15u | G22: =IF($H22="",3,LEN($H22)-LEN(SUBSTITUTE($H22,",",""))+1) -> 3
A23: 45987 | B23: wo | C23: 31 | D23: =IF(AND($H23="",$I23=""),"",SUMPRODUCT(--ISNUMBER(SEARCH(","&Verpleegkundigen!$C$2:$C$100&",",","&LOWER(SUBSTITUTE(SUBSTITUTE($H23," ",""),CHAR(160),""))&","))*(Verpleegkundigen!$C$2:$C$100<>LOWER(SUBSTITUTE(SUBSTITUTE($I23," ",""),CHAR(160),""))),Verpleegkundigen!$B$2:$B$100)+IF($I23<>"",1,0)) | E23: =IF(AND(C23<>"",D23<>"",C23>D23),"+" & TEXT(C23-D23,"0"),"") | F23: Irma 4e, Yvonne tot 14u | G23: =IF($H23="",4,LEN($H23)-LEN(SUBSTITUTE($H23,",",""))+1) -> 4
A24: 45988 | B24: do | C24: 30 | D24: =IF(AND($H24="",$I24=""),"",SUMPRODUCT(--ISNUMBER(SEARCH(","&Verpleegkundigen!$C$2:$C$100&",",","&LOWER(SUBSTITUTE(SUBSTITUTE($H24," ",""),CHAR(160),""))&","))*(Verpleegkundigen!$C$2:$C$100<>LOWER(SUBSTITUTE(SUBSTITUTE($I24," ",""),CHAR(160),""))),Verpleegkundigen!$B$2:$B$100)+IF($I24<>"",1,0)) | E24: =IF(AND(C24<>"",D24<>"",C24>D24),"+" & TEXT(C24-D24,"0"),"") | F24: Merel overleg 14.00 /15.00 | G24: =IF($H24="",4,LEN($H24)-LEN(SUBSTITUTE($H24,",",""))+1) -> 4
A25: 45989 | B25: vr | C25: 18 | D25: 17 | E25: =IF(AND(C25<>"",D25<>"",C25>D25),"+" & TEXT(C25-D25,"0"),"") -> +1 | F25: (Evt flex ) + 2 mag blijven staan | G25: =IF($H25="",3,LEN($H25)-LEN(SUBSTITUTE($H25,",",""))+1) -> 3 | H25: irma, sanne, ailien | I25: sanne

Sheet Dec '25
A1: Datum | B1: Weekdag | C1: Aantal patiënten | D1: Max aantal patiënten afgesproken | F1: Max Capaciteit | G1: Overschrijding | H1: Opmerking | I1: Aantal vpk | J1: Naam verpleegkundige | K1: Dagco (naam) | L1: Opmerkingen Senna
A2: Week 49
A3: 45992 | B3: ma | C3: 30 | D3: 30 | E3: =IF(F3>D3,1,IF(F3=D3,0,-1)) -> 0 | F3: 30 | G3: =IF(AND(C3<>"",D3<>"",C3>D3),"+" & TEXT(C3-D3,"0"),"") | H3: Yvonne tot 15:30u | I3: =IF($J3="",4,LEN($J3)-LEN(SUBSTITUTE($J3,",",""))+1) -> 4 | J3: henriette, suzan, merel, yvonne | K3: henriette
A4: 45993 | B4: di | C4: 29 | D4: 29 | E4: =IF(F4>D4,1,IF(F4=D4,0,-1)) -> 1 | F4: 31 | G4: =IF(AND(C4<>"",D4<>"",C4>D4),"+" & TEXT(C4-D4,"0"),"") | H4: 29 (4e is Irma) | I4: =IF($J4="",4,LEN($J4)-LEN(SUBSTITUTE($J4,",",""))+1) -> 4 | J4: henriette, suzan, irma, merel | K4: suzan
A5: 45994 | B5: wo | C5: 22 | D5: 20 | E5: =IF(F5>D5,1,IF(F5=D5,0,-1)) -> 0 | F5: 20 | G5: =IF(AND(C5<>"",D5<>"",C5>D5),"+" & TEXT(C5-D5,"0"),"") -> +2 | H5: yvonne tot 15;30 uur | I5: =IF($J5="",3,LEN($J5)-LEN(SUBSTITUTE($J5,",",""))+1) -> 3 | J5: joyce, merel, yvonne | K5: merel
A6: 45995 | B6: do | C6: 32 | D6: 32 | E6: =IF(F6>D6,1,IF(F6=D6,0,-1)) -> 1 | F6: 33 | G6: =IF(AND(C6<>"",D6<>"",C6>D6),"+" & TEXT(C6-D6,"0"),"") | H6: Sarina is er (mag naar 32) | 27 (Yvonne tot 14u, 4e is Irma) | I6: =IF($J6="",4,LEN($J6)-LEN(SUBSTITUTE($J6,",",""))+1) -> 5 | J6: henriette, suzan, irma, yvonne, sarina | K6: henriette
A7: 45996 | B7: vr | C7: 24 | D7: 21 | E7: =IF(F7>D7,1,IF(F7=D7,0,-1)) -> 0 | F7: 21 | G7: =IF(AND(C7<>"",D7<>"",C7>D7),"+" & TEXT(C7-D7,"0"),"") -> +3 | H7: 21 (Yvonne tot 14u) (irma 3e) + flex Vera | I7: =IF($J7="",3,LEN($J7)-LEN(SUBSTITUTE($J7,",",""))+1) -> 3 | J7: carla, joyce, irma | K7: joyce
A8: Week 50 | F8: =IF(AND($J8="",$K8=""),"",SUMPRODUCT(--ISNUMBER(SEARCH(","&Verpleegkundigen!$C$2:$C$100&",",","&LOWER(SUBSTITUTE(SUBSTITUTE($J8," ",""),CHAR(160),""))&","))*(Verpleegkundigen!$C$2:$C$100<>LOWER(SUBSTITUTE(SUBSTITUTE($K8," ",""),CHAR(160),""))),Verpleegkundigen!$B$2:$B$100)+IF($K8<>"",1,0))
A9: 45999 | B9: ma | C9: 30 | D9: 29 | E9: =IF(F9>D9,1,IF(F9=D9,0,-1)) -> 1 | F9: 31 | G9: =IF(AND(C9<>"",D9<>"",C9>D9),"+" & TEXT(C9-D9,"0"),"") -> +1 | H9: 29. 11:30-12:30 1 vpk minder | I9: =IF($J9="",4,LEN($J9)-LEN(SUBSTITUTE($J9,",",""))+1) -> 4 | J9: henriette, suzan, irma, merel | K9: henriette
A10: 46000 | B10: di | C10: 37 | D10: 37 | E10: =IF(F10>D10,1,IF(F10=D10,0,-1)) -> -1 | F10: 30 | G10: =IF(AND(C10<>"",D10<>"",C10>D10),"+" & TEXT(C10-D10,"0"),"") | I10: =IF($J10="",4,LEN($J10)-LEN(SUBSTITUTE($J10,",",""))+1) -> 4 | J10: henriette, suzan, merel, yvonne | K10: merel | L10: Sanne is erbij gekomen tot 14:0
A11: 46001 | B11: wo | C11: 29 | D11: 29 | E11: =IF(F11>D11,1,IF(F11=D11,0,-1)) -> -1 | F11: 24 | G11: =IF(AND(C11<>"",D11<>"",C11>D11),"+" & TEXT(C11-D11,"0"),"") | H11: Merel komt extra 9-13u (=dagco) Sarina is er 9.30-14u | I11: =IF($J11="",3,LEN($J11)-LEN(SUBSTITUTE($J11,",",""))+1) -> 4 | J11: henriette, joyce, irma, sarina | K11: joyce | L11: Merel is er bij gekomen 09:00-13:00
A12: 46002 | B12: do | C12: 28 | D12: 29 | E12: =IF(F12>D12,1,IF(F12=D12,0,-1)) -> 1 | F12: 30 | G12: =IF(AND(C12<>"",D12<>"",C12>D12),"+" & TEXT(C12-D12,"0"),"") | H12: 27 (Yvonne tot 15,30u, Irma 4e) IVM NO-SHOW niet vol | I12: =IF($J12="",4,LEN($J12)-LEN(SUBSTITUTE($J12,",",""))+1) -> 5 | J12: henriette, suzan, irma, yvonne, | K12: suzan
A13: 46003 | B13: vr | C13: 21 | D13: 21 | E13: =IF(F13>D13,1,IF(F13=D13,0,-1)) -> 0 | F13: 21 | G13: =IF(AND(C13<>"",D13<>"",C13>D13),"+" & TEXT(C13-D13,"0"),"") | H13: 21 | I13: =IF($J13="",3,LEN($J13)-LEN(SUBSTITUTE($J13,",",""))+1) -> 4 | J13: carla, sanne, joyce, | K13: sanne
A14: Week 51 | F14: =IF(AND($J14="",$K14=""),"",SUMPRODUCT(--ISNUMBER(SEARCH(","&Verpleegkundigen!$C$2:$C$100&",",","&LOWER(SUBSTITUTE(SUBSTITUTE($J14," ",""),CHAR(160),""))&","))*(Verpleegkundigen!$C$2:$C$100<>LOWER(SUBSTITUTE(SUBSTITUTE($K14," ",""),CHAR(160),""))),Verpleegkundigen!$B$2:$B$100)+IF($K14<>"",1,0))
A15: 46006 | B15: ma | C15: 41 | D15: 41 | E15: =IF(F15>D15,1,IF(F15=D15,0,-1)) -> -1 | F15: 40 | G15: =IF(AND(C15<>"",D15<>"",C15>D15),"+" & TEXT(C15-D15,"0"),"") | H15: 27 (Yvonne tot 16,30u, 5e is Irma) en Sarina 9.30-11.30u | I15: =IF($J15="",4,LEN($J15)-LEN(SUBSTITUTE($J15,",",""))+1) -> 5 | J15: henriette, irma, merel, yvonne, sanne | K15: henriette
A16: 46007 | B16: di | C16: 31 | D16: 31 | E16: =IF(F16>D16,1,IF(F16=D16,0,-1)) -> 0 | F16: 31 | G16: =IF(AND(C16<>"",D16<>"",C16>D16),"+" & TEXT(C16-D16,"0"),"") | H16: 21 (4e is Irma) | I16: =IF($J16="",3,LEN($J16)-LEN(SUBSTITUTE($J16,",",""))+1) -> 4 | J16: henriette, irma, merel, sanne | K16: merel
A17: 46008 | B17: wo | C17: 29 | D17: 29 | E17: =IF(F17>D17,1,IF(F17=D17,0,-1)) -> 1 | F17: 30 | G17: =IF(AND(C17<>"",D17<>"",C17>D17),"+" & TEXT(C17-D17,"0"),"") | H17: 29 (Yvonne tot 15,30u en Henriette tot 14u) HENRIETTE OM 10;15 EVEN WEG | I17: =IF($J17="",4,LEN($J17)-LEN(SUBSTITUTE($J17,",",""))+1) -> 4 | J17: henriette, carla, suzan, yvonne | K17: suzan
A18: 46009 | B18: do | C18: 25 | D18: 25 | E18: =IF(F18>D18,1,IF(F18=D18,0,-1)) -> -1 | F18: 24 | G18: =IF(AND(C18<>"",D18<>"",C18>D18),"+" & TEXT(C18-D18,"0"),"") | H18: Sarina is er (mag naar 25) | I18: =IF($J18="",3,LEN($J18)-LEN(SUBSTITUTE($J18,",",""))+1) -> 4 | J18: henriette, suzan, merel, sarina | K18: henriette
A19: 46010 | B19: vr | C19: 21 | D19: 20 | E19: =IF(F19>D19,1,IF(F19=D19,0,-1)) -> 0 | F19: 20 | G19: =IF(AND(C19<>"",D19<>"",C19>D19),"+" & TEXT(C19-D19,"0"),"") -> +1 | H19: 21 (Yvonne tot 16,30) | I19: =IF($J19="",3,LEN($J19)-LEN(SUBSTITUTE($J19,",",""))+1) -> 3 | J19: carla, irma, yvonne | K19: carla
A20: Week 52 | F20: =IF(AND($J20="",$K20=""),"",SUMPRODUCT(--ISNUMBER(SEARCH(","&Verpleegkundigen!$C$2:$C$100&",",","&LOWER(SUBSTITUTE(SUBSTITUTE($J20," ",""),CHAR(160),""))&","))*(Verpleegkundigen!$C$2:$C$100<>LOWER(SUBSTITUTE(SUBSTITUTE($K20," ",""),CHAR(160),""))),Verpleegkundigen!$B$2:$B$100)+IF($K20<>"",1,0))
A21: 46013 | B21: ma | C21: 35 | D21: 35 | E21: =IF(F21>D21,1,IF(F21=D21,0,-1)) -> 1 | F21: =IF(AND($J21="",$K21=""),"",SUMPRODUCT(--ISNUMBER(SEARCH(","&Verpleegkundigen!$C$2:$C$100&",",","&LOWER(SUBSTITUTE(SUBSTITUTE($J21," ",""),CHAR(160),""))&","))*(Verpleegkundigen!$C$2:$C$100<>LOWER(SUBSTITUTE(SUBSTITUTE($K21," ",""),CHAR(160),""))),Verpleegkundigen!$B$2:$B$100)+IF($K21<>"",1,0)) -> 36 | G21: =IF(AND(C21<>"",D21<>"",C21>D21),"+" & TEXT(C21-D21,"0"),"") | H21: Sarina 9,30-14u (mag naar 35) | I21: =IF($J21="",4,LEN($J21)-LEN(SUBSTITUTE($J21,",",""))+1) -> 5 | J21: henriette, suzan, irma, merel, sarina | K21: suzan
A22: 46014 | B22: di | C22: 32 | D22: =IF(AND($J22="",$K22=""),"",SUMPRODUCT(--ISNUMBER(SEARCH(","&Verpleegkundigen!$C$2:$C$100&",",","&LOWER(SUBSTITUTE(SUBSTITUTE($J22," ",""),CHAR(160),""))&","))*(Verpleegkundigen!$C$2:$C$100<>LOWER(SUBSTITUTE(SUBSTITUTE($K22," ",""),CHAR(160),""))),Verpleegkundigen!$B$2:$B$100)+IF($K22<>"",1,0)) -> 31 | E22: =IF(F22>D22,1,IF(F22=D22,0,-1)) -> 0 | F22: =IF(AND($J22="",$K22=""),"",SUMPRODUCT(--ISNUMBER(SEARCH(","&Verpleegkundigen!$C$2:$C$100&",",","&LOWER(SUBSTITUTE(SUBSTITUTE($J22," ",""),CHAR(160),""))&","))*(Verpleegkundigen!$C$2:$C$100<>LOWER(SUBSTITUTE(SUBSTITUTE($K22," ",""),CHAR(160),""))),Verpleegkundigen!$B$2:$B$100)+IF($K22<>"",1,0)) -> 31 | G22: =IF(AND(C22<>"",D22<>"",C22>D22),"+" & TEXT(C22-D22,"0"),"") -> +1 | H22: Yvonne tot 16.30 | I22: =IF($J22="",4,LEN($J22)-LEN(SUBSTITUTE($J22,",",""))+1) -> 4 | J22: carla, joyce, irma, yvonne | K22: joyce
A23: 46015 | B23: wo | C23: 24 | D23: 21 | E23: =IF(F23>D23,1,IF(F23=D23,0,-1)) -> 0 | F23: =IF(AND($J23="",$K23=""),"",SUMPRODUCT(--ISNUMBER(SEARCH(","&Verpleegkundigen!$C$2:$C$100&",",","&LOWER(SUBSTITUTE(SUBSTITUTE($J23," ",""),CHAR(160),""))&","))*(Verpleegkundigen!$C$2:$C$100<>LOWER(SUBSTITUTE(SUBSTITUTE($K23," ",""),CHAR(160),""))),Verpleegkundigen!$B$2:$B$100)+IF($K23<>"",1,0)) -> 21 | G23: =IF(AND(C23<>"",D23<>"",C23>D23),"+" & TEXT(C23-D23,"0"),"") -> +3 | H23: Yvonne tot 16.30, joyce erbij van 09:00-13:00 | I23: =IF($J23="",3,LEN($J23)-LEN(SUBSTITUTE($J23,",",""))+1) -> 3 | J23: merel, yvonne, joyce | K23: joyce | L23: 19/12 henriette eraf en joyce e4rbij van 09:00-13:00
A24: 46016 | B24: do | D24: =IF(AND($J24="",$K24=""),"",SUMPRODUCT(--ISNUMBER(SEARCH(","&Verpleegkundigen!$C$2:$C$100&",",","&LOWER(SUBSTITUTE(SUBSTITUTE($J24," ",""),CHAR(160),""))&","))*(Verpleegkundigen!$C$2:$C$100<>LOWER(SUBSTITUTE(SUBSTITUTE($K24," ",""),CHAR(160),""))),Verpleegkundigen!$B$2:$B$100)+IF($K24<>"",1,0)) | F24: =IF(AND($J24="",$K24=""),"",SUMPRODUCT(--ISNUMBER(SEARCH(","&Verpleegkundigen!$C$2:$C$100&",",","&LOWER(SUBSTITUTE(SUBSTITUTE($J24," ",""),CHAR(160),""))&","))*(Verpleegkundigen!$C$2:$C$100<>LOWER(SUBSTITUTE(SUBSTITUTE($K24," ",""),CHAR(160),""))),Verpleegkundigen!$B$2:$B$100)+IF($K24<>"",1,0)) | G24: =IF(AND(C24<>"",D24<>"",C24>D24),"+" & TEXT(C24-D24,"0"),"") | H24: DICHT | I24: =IF($J24="","",LEN($J24)-LEN(SUBSTITUTE($J24,",",""))+1)
A25: 46017 | B25: vr | D25: =IF(AND($J25="",$K25=""),"",SUMPRODUCT(--ISNUMBER(SEARCH(","&Verpleegkundigen!$C$2:$C$100&",",","&LOWER(SUBSTITUTE(SUBSTITUTE($J25," ",""),CHAR(160),""))&","))*(Verpleegkundigen!$C$2:$C$100<>LOWER(SUBSTITUTE(SUBSTITUTE($K25," ",""),CHAR(160),""))),Verpleegkundigen!$B$2:$B$100)+IF($K25<>"",1,0)) | F25: =IF(AND($J25="",$K25=""),"",SUMPRODUCT(--ISNUMBER(SEARCH(","&Verpleegkundigen!$C$2:$C$100&",",","&LOWER(SUBSTITUTE(SUBSTITUTE($J25," ",""),CHAR(160),""))&","))*(Verpleegkundigen!$C$2:$C$100<>LOWER(SUBSTITUTE(SUBSTITUTE($K25," ",""),CHAR(160),""))),Verpleegkundigen!$B$2:$B$100)+IF($K25<>"",1,0)) | G25: =IF(AND(C25<>"",D25<>"",C25>D25),"+" & TEXT(C25-D25,"0"),"") | H25: DICHT | I25: =IF($J25="","",LEN($J25)-LEN(SUBSTITUTE($J25,",",""))+1)
A26: Week 1 | F26: =IF(AND($J26="",$K26=""),"",SUMPRODUCT(--ISNUMBER(SEARCH(","&Verpleegkundigen!$C$2:$C$100&",",","&LOWER(SUBSTITUTE(SUBSTITUTE($J26," ",""),CHAR(160),""))&","))*(Verpleegkundigen!$C$2:$C$100<>LOWER(SUBSTITUTE(SUBSTITUTE($K26," ",""),CHAR(160),""))),Verpleegkundigen!$B$2:$B$100)+IF($K26<>"",1,0))
A27: 46020 | B27: ma | C27: 33 | D27: =IF(AND($J27="",$K27=""),"",SUMPRODUCT(--ISNUMBER(SEARCH(","&Verpleegkundigen!$C$2:$C$100&",",","&LOWER(SUBSTITUTE(SUBSTITUTE($J27," ",""),CHAR(160),""))&","))*(Verpleegkundigen!$C$2:$C$100<>LOWER(SUBSTITUTE(SUBSTITUTE($K27," ",""),CHAR(160),""))),Verpleegkundigen!$B$2:$B$100)+IF($K27<>"",1,0)) -> 31 | E27: =IF(F27>D27,1,IF(F27=D27,0,-1)) -> 0 | F27: =IF(AND($J27="",$K27=""),"",SUMPRODUCT(--ISNUMBER(SEARCH(","&Verpleegkundigen!$C$2:$C$100&",",","&LOWER(SUBSTITUTE(SUBSTITUTE($J27," ",""),CHAR(160),""))&","))*(Verpleegkundigen!$C$2:$C$100<>LOWER(SUBSTITUTE(SUBSTITUTE($K27," ",""),CHAR(160),""))),Verpleegkundigen!$B$2:$B$100)+IF($K27<>"",1,0)) -> 31 | G27: =IF(AND(C27<>"",D27<>"",C27>D27),"+" & TEXT(C27-D27,"0"),"") -> +2 | H27: 29 | I27: =IF($J27="",4,LEN($J27)-LEN(SUBSTITUTE($J27,",",""))+1) -> 4 | J27: joyce, irma, merel, yvonne | K27: joyce
A28: 46021 | B28: di | C28: 32 | D28: =IF(AND($J28="",$K28=""),"",SUMPRODUCT(--ISNUMBER(SEARCH(","&Verpleegkundigen!$C$2:$C$100&",",","&LOWER(SUBSTITUTE(SUBSTITUTE($J28," ",""),CHAR(160),""))&","))*(Verpleegkundigen!$C$2:$C$100<>LOWER(SUBSTITUTE(SUBSTITUTE($K28," ",""),CHAR(160),""))),Verpleegkundigen!$B$2:$B$100)+IF($K28<>"",1,0)) -> 31 | E28: =IF(F28>D28,1,IF(F28=D28,0,-1)) -> 0 | F28: =IF(AND($J28="",$K28=""),"",SUMPRODUCT(--ISNUMBER(SEARCH(","&Verpleegkundigen!$C$2:$C$100&",",","&LOWER(SUBSTITUTE(SUBSTITUTE($J28," ",""),CHAR(160),""))&","))*(Verpleegkundigen!$C$2:$C$100<>LOWER(SUBSTITUTE(SUBSTITUTE($K28," ",""),CHAR(160),""))),Verpleegkundigen!$B$2:$B$100)+IF($K28<>"",1,0)) -> 31 | G28: =IF(AND(C28<>"",D28<>"",C28>D28),"+" & TEXT(C28-D28,"0"),"") -> +1 | H28: 29 | I28: =IF($J28="",4,LEN($J28)-LEN(SUBSTITUTE($J28,",",""))+1) -> 4 | J28: carla, irma, merel, yvonne | K28: merel
A29: 46022 | B29: wo | C29: 24 | D29: =IF(AND($J29="",$K29=""),"",SUMPRODUCT(--ISNUMBER(SEARCH(","&Verpleegkundigen!$C$2:$C$100&",",","&LOWER(SUBSTITUTE(SUBSTITUTE($J29," ",""),CHAR(160),""))&","))*(Verpleegkundigen!$C$2:$C$100<>LOWER(SUBSTITUTE(SUBSTITUTE($K29," ",""),CHAR(160),""))),Verpleegkundigen!$B$2:$B$100)+IF($K29<>"",1,0)) -> 21 | E29: =IF(F29>D29,1,IF(F29=D29,0,-1)) -> 0 | F29: =IF(AND($J29="",$K29=""),"",SUMPRODUCT(--ISNUMBER(SEARCH(","&Verpleegkundigen!$C$2:$C$100&",",","&LOWER(SUBSTITUTE(SUBSTITUTE($J29," ",""),CHAR(160),""))&","))*(Verpleegkundigen!$C$2:$C$100<>LOWER(SUBSTITUTE(SUBSTITUTE($K29," ",""),CHAR(160),""))),Verpleegkundigen!$B$2:$B$100)+IF($K29<>"",1,0)) -> 21 | G29: =IF(AND(C29<>"",D29<>"",C29>D29),"+" & TEXT(C29-D29,"0"),"") -> +3 | H29: 21 | I29: =IF($J29="",3,LEN($J29)-LEN(SUBSTITUTE($J29,",",""))+1) -> 3 | J29: sanne, joyce, irma | K29: sanne

Sheet Jan '26
A1: Datum | B1: Weekdag | C1: Aantal patiënten | D1: Max aantal patiënten afgesproken | F1: Max Capaciteit | G1: Overschrijding | H1: Opmerking | I1: Aantal vpk | J1: Naam verpleegkundige | K1: Dagco (naam) | L1: Opmerkingen Senna
A2: Week 1
A3: 46023 | B3: do | D3: =IF(AND($J3="",$K3=""),"",SUMPRODUCT(--ISNUMBER(SEARCH(","&Verpleegkundigen!$C$2:$C$100&",",","&LOWER(SUBSTITUTE(SUBSTITUTE($J3," ",""),CHAR(160),""))&","))*(Verpleegkundigen!$C$2:$C$100<>LOWER(SUBSTITUTE(SUBSTITUTE($K3," ",""),CHAR(160),""))),Verpleegkundigen!$B$2:$B$100)+IF($K3<>"",1,0)) | F3: =IF(AND($J3="",$K3=""),"",SUMPRODUCT(--ISNUMBER(SEARCH(","&Verpleegkundigen!$C$2:$C$100&",",","&LOWER(SUBSTITUTE(SUBSTITUTE($J3," ",""),CHAR(160),""))&","))*(Verpleegkundigen!$C$2:$C$100<>LOWER(SUBSTITUTE(SUBSTITUTE($K3," ",""),CHAR(160),""))),Verpleegkundigen!$B$2:$B$100)+IF($K3<>"",1,0)) | G3: =IF(AND(C3<>"",D3<>"",C3>D3),"+" & TEXT(C3-D3,"0"),"") | H3: DICHT | I3: =IF($J3="","",LEN($J3)-LEN(SUBSTITUTE($J3,",",""))+1)
A4: 46024 | B4: vr | C4: 23 | D4: 18 | E4: =IF(F4>D4,1,IF(F4=D4,0,-1)) -> 1 | F4: =IF(AND($J4="",$K4=""),"",SUMPRODUCT(--ISNUMBER(SEARCH(","&Verpleegkundigen!$C$2:$C$100&",",","&LOWER(SUBSTITUTE(SUBSTITUTE($J4," ",""),CHAR(160),""))&","))*(Verpleegkundigen!$C$2:$C$100<>LOWER(SUBSTITUTE(SUBSTITUTE($K4," ",""),CHAR(160),""))),Verpleegkundigen!$B$2:$B$100)+IF($K4<>"",1,0)) -> 21 | G4: =IF(AND(C4<>"",D4<>"",C4>D4),"+" & TEXT(C4-D4,"0"),"") -> +5 | H4: 21 aanhouden, Sarina 09:30-14:30 | I4: =IF($J4="",3,LEN($J4)-LEN(SUBSTITUTE($J4,",",""))+1) -> 3 | J4: carla, sarina, yvonne | K4: Sarina | L4: 15dec: flex?
A5: Week 2 | F5: =IF(AND($J5="",$K5=""),"",SUMPRODUCT(--ISNUMBER(SEARCH(","&Verpleegkundigen!$C$2:$C$100&",",","&LOWER(SUBSTITUTE(SUBSTITUTE($J5," ",""),CHAR(160),""))&","))*(Verpleegkundigen!$C$2:$C$100<>LOWER(SUBSTITUTE(SUBSTITUTE($K5," ",""),CHAR(160),""))),Verpleegkundigen!$B$2:$B$100)+IF($K5<>"",1,0))
A6: 46027 | B6: ma | C6: 31 | D6: 31 | E6: =IF(F6>D6,1,IF(F6=D6,0,-1)) -> 0 | F6: =IF(AND($J6="",$K6=""),"",SUMPRODUCT(--ISNUMBER(SEARCH(","&Verpleegkundigen!$C$2:$C$100&",",","&LOWER(SUBSTITUTE(SUBSTITUTE($J6," ",""),CHAR(160),""))&","))*(Verpleegkundigen!$C$2:$C$100<>LOWER(SUBSTITUTE(SUBSTITUTE($K6," ",""),CHAR(160),""))),Verpleegkundigen!$B$2:$B$100)+IF($K6<>"",1,0)) -> 31 | G6: =IF(AND(C6<>"",D6<>"",C6>D6),"+" & TEXT(C6-D6,"0"),"") | H6: 31 aanhouden | I6: =IF($J6="",4,LEN($J6)-LEN(SUBSTITUTE($J6,",",""))+1) -> 4 | J6: henriette, suzan, irma, merel | K6: merel | L6: 15dec: Sarina 9.30-12u, nader afstemmen hoeveel patiënten
A7: 46028 | B7: di | C7: 32 | D7: 31 | E7: =IF(F7>D7,1,IF(F7=D7,0,-1)) -> 0 | F7: =IF(AND($J7="",$K7=""),"",SUMPRODUCT(--ISNUMBER(SEARCH(","&Verpleegkundigen!$C$2:$C$100&",",","&LOWER(SUBSTITUTE(SUBSTITUTE($J7," ",""),CHAR(160),""))&","))*(Verpleegkundigen!$C$2:$C$100<>LOWER(SUBSTITUTE(SUBSTITUTE($K7," ",""),CHAR(160),""))),Verpleegkundigen!$B$2:$B$100)+IF($K7<>"",1,0)) -> 31 | G7: =IF(AND(C7<>"",D7<>"",C7>D7),"+" & TEXT(C7-D7,"0"),"") -> +1 | H7: 31 aanhouden | I7: =IF($J7="",4,LEN($J7)-LEN(SUBSTITUTE($J7,",",""))+1) -> 4 | J7: henriette, suzan, irma, merel | K7: suzan
A8: 46029 | B8: wo | C8: 32 | D8: 31 | E8: =IF(F8>D8,1,IF(F8=D8,0,-1)) -> 0 | F8: =IF(AND($J8="",$K8=""),"",SUMPRODUCT(--ISNUMBER(SEARCH(","&Verpleegkundigen!$C$2:$C$100&",",","&LOWER(SUBSTITUTE(SUBSTITUTE($J8," ",""),CHAR(160),""))&","))*(Verpleegkundigen!$C$2:$C$100<>LOWER(SUBSTITUTE(SUBSTITUTE($K8," ",""),CHAR(160),""))),Verpleegkundigen!$B$2:$B$100)+IF($K8<>"",1,0)) -> 31 | G8: =IF(AND(C8<>"",D8<>"",C8>D8),"+" & TEXT(C8-D8,"0"),"") -> +1 | H8: 31 aanhouden | I8: =IF($J8="",4,LEN($J8)-LEN(SUBSTITUTE($J8,",",""))+1) -> 4 | J8: henriette, sanne, merel, yvonne | K8: sanne
A9: 46030 | B9: do | C9: 31 | D9: 31 | E9: =IF(F9>D9,1,IF(F9=D9,0,-1)) -> 1 | F9: =IF(AND($J9="",$K9=""),"",SUMPRODUCT(--ISNUMBER(SEARCH(","&Verpleegkundigen!$C$2:$C$100&",",","&LOWER(SUBSTITUTE(SUBSTITUTE($J9," ",""),CHAR(160),""))&","))*(Verpleegkundigen!$C$2:$C$100<>LOWER(SUBSTITUTE(SUBSTITUTE($K9," ",""),CHAR(160),""))),Verpleegkundigen!$B$2:$B$100)+IF($K9<>"",1,0)) -> 36 | G9: =IF(AND(C9<>"",D9<>"",C9>D9),"+" & TEXT(C9-D9,"0"),"") | H9: 31 aanhouden, Sarina 9.30-14.30u | I9: =IF($J9="",4,LEN($J9)-LEN(SUBSTITUTE($J9,",",""))+1) -> 5 | J9: henriette, suzan, sarina, irma, yvonne | K9: henriette
A10: 46031 | B10: vr | C10: 36 | D10: 36 | E10: =IF(F10>D10,1,IF(F10=D10,0,-1)) -> 1 | F10: =IF(AND($J10="",$K10=""),"",SUMPRODUCT(--ISNUMBER(SEARCH(","&Verpleegkundigen!$C$2:$C$100&",",","&LOWER(SUBSTITUTE(SUBSTITUTE($J10," ",""),CHAR(160),""))&","))*(Verpleegkundigen!$C$2:$C$100<>LOWER(SUBSTITUTE(SUBSTITUTE($K10," ",""),CHAR(160),""))),Verpleegkundigen!$B$2:$B$100)+IF($K10<>"",1,0)) -> 41 | G10: =IF(AND(C10<>"",D10<>"",C10>D10),"+" & TEXT(C10-D10,"0"),"") | H10: 31 aanhouden | I10: =IF($J10="",4,LEN($J10)-LEN(SUBSTITUTE($J10,",",""))+1) -> 5 | J10: carla, joyce, irma, yvonne, sanne | K10: joyce
A11: Week 3 | F11: =IF(AND($J11="",$K11=""),"",SUMPRODUCT(--ISNUMBER(SEARCH(","&Verpleegkundigen!$C$2:$C$100&",",","&LOWER(SUBSTITUTE(SUBSTITUTE($J11," ",""),CHAR(160),""))&","))*(Verpleegkundigen!$C$2:$C$100<>LOWER(SUBSTITUTE(SUBSTITUTE($K11," ",""),CHAR(160),""))),Verpleegkundigen!$B$2:$B$100)+IF($K11<>"",1,0))
A12: 46034 | B12: ma | C12: 30 | D12: 31 | E12: =IF(F12>D12,1,IF(F12=D12,0,-1)) -> 0 | F12: =IF(AND($J12="",$K12=""),"",SUMPRODUCT(--ISNUMBER(SEARCH(","&Verpleegkundigen!$C$2:$C$100&",",","&LOWER(SUBSTITUTE(SUBSTITUTE($J12," ",""),CHAR(160),""))&","))*(Verpleegkundigen!$C$2:$C$100<>LOWER(SUBSTITUTE(SUBSTITUTE($K12," ",""),CHAR(160),""))),Verpleegkundigen!$B$2:$B$100)+IF($K12<>"",1,0)) -> 31 | G12: =IF(AND(C12<>"",D12<>"",C12>D12),"+" & TEXT(C12-D12,"0"),"") | H12: 31 aanhouden | I12: =IF($J12="",4,LEN($J12)-LEN(SUBSTITUTE($J12,",",""))+1) -> 4 | J12: hernriette, suzan, merel, yvonne | K12: henriette | L12: 15dec: Sarina 9.30-12,30u, nader afstemmen hoeveel patiënten
A13: 46035 | B13: di | C13: 30 | D13: 31 | E13: =IF(F13>D13,1,IF(F13=D13,0,-1)) -> 1 | F13: =IF(AND($J13="",$K13=""),"",SUMPRODUCT(--ISNUMBER(SEARCH(","&Verpleegkundigen!$C$2:$C$100&",",","&LOWER(SUBSTITUTE(SUBSTITUTE($J13," ",""),CHAR(160),""))&","))*(Verpleegkundigen!$C$2:$C$100<>LOWER(SUBSTITUTE(SUBSTITUTE($K13," ",""),CHAR(160),""))),Verpleegkundigen!$B$2:$B$100)+IF($K13<>"",1,0)) -> 41 | G13: =IF(AND(C13<>"",D13<>"",C13>D13),"+" & TEXT(C13-D13,"0"),"") | H13: 31 aanhouden | I13: =IF($J13="",4,LEN($J13)-LEN(SUBSTITUTE($J13,",",""))+1) -> 5 | J13: henriette, carla, joyce, irma, merel | K13: merel
A14: 46036 | B14: wo | C14: 30 | D14: 31 | E14: =IF(F14>D14,1,IF(F14=D14,0,-1)) -> -1 | F14: =IF(AND($J14="",$K14=""),"",SUMPRODUCT(--ISNUMBER(SEARCH(","&Verpleegkundigen!$C$2:$C$100&",",","&LOWER(SUBSTITUTE(SUBSTITUTE($J14," ",""),CHAR(160),""))&","))*(Verpleegkundigen!$C$2:$C$100<>LOWER(SUBSTITUTE(SUBSTITUTE($K14," ",""),CHAR(160),""))),Verpleegkundigen!$B$2:$B$100)+IF($K14<>"",1,0)) -> 27 | G14: =IF(AND(C14<>"",D14<>"",C14>D14),"+" & TEXT(C14-D14,"0"),"") | H14: 31 aanhouden | I14: =IF($J14="",4,LEN($J14)-LEN(SUBSTITUTE($J14,",",""))+1) -> 4 | J14: sanne, irma, lisa, yvonne | K14: sanne
A15: 46037 | B15: do | C15: 29 | D15: 31 | E15: =IF(F15>D15,1,IF(F15=D15,0,-1)) -> 1 | F15: =IF(AND($J15="",$K15=""),"",SUMPRODUCT(--ISNUMBER(SEARCH(","&Verpleegkundigen!$C$2:$C$100&",",","&LOWER(SUBSTITUTE(SUBSTITUTE($J15," ",""),CHAR(160),""))&","))*(Verpleegkundigen!$C$2:$C$100<>LOWER(SUBSTITUTE(SUBSTITUTE($K15," ",""),CHAR(160),""))),Verpleegkundigen!$B$2:$B$100)+IF($K15<>"",1,0)) -> 36 | G15: =IF(AND(C15<>"",D15<>"",C15>D15),"+" & TEXT(C15-D15,"0"),"") | H15: 31 aanhouden,Sarina 9.30-14.30u | I15: =IF($J15="",4,LEN($J15)-LEN(SUBSTITUTE($J15,",",""))+1) -> 5 | J15: henriette, suzan, sarina, merel, yvonne | K15: suzan
A16: 46038 | B16: vr | C16: 30 | D16: 31 | E16: =IF(F16>D16,1,IF(F16=D16,0,-1)) -> 1 | F16: =IF(AND($J16="",$K16=""),"",SUMPRODUCT(--ISNUMBER(SEARCH(","&Verpleegkundigen!$C$2:$C$100&",",","&LOWER(SUBSTITUTE(SUBSTITUTE($J16," ",""),CHAR(160),""))&","))*(Verpleegkundigen!$C$2:$C$100<>LOWER(SUBSTITUTE(SUBSTITUTE($K16," ",""),CHAR(160),""))),Verpleegkundigen!$B$2:$B$100)+IF($K16<>"",1,0)) -> 37 | G16: =IF(AND(C16<>"",D16<>"",C16>D16),"+" & TEXT(C16-D16,"0"),"") | H16: 31 aanhouden | I16: =IF($J16="",4,LEN($J16)-LEN(SUBSTITUTE($J16,",",""))+1) -> 5 | J16: carla, sanne, joyce, irma, lisa | K16: joyce
A17: Week 4 | F17: =IF(AND($J17="",$K17=""),"",SUMPRODUCT(--ISNUMBER(SEARCH(","&Verpleegkundigen!$C$2:$C$100&",",","&LOWER(SUBSTITUTE(SUBSTITUTE($J17," ",""),CHAR(160),""))&","))*(Verpleegkundigen!$C$2:$C$100<>LOWER(SUBSTITUTE(SUBSTITUTE($K17," ",""),CHAR(160),""))),Verpleegkundigen!$B$2:$B$100)+IF($K17<>"",1,0))
A18: 46041 | B18: ma | C18: 30 | D18: 31 | E18: =IF(F18>D18,1,IF(F18=D18,0,-1)) -> 1 | F18: =IF(AND($J18="",$K18=""),"",SUMPRODUCT(--ISNUMBER(SEARCH(","&Verpleegkundigen!$C$2:$C$100&",",","&LOWER(SUBSTITUTE(SUBSTITUTE($J18," ",""),CHAR(160),""))&","))*(Verpleegkundigen!$C$2:$C$100<>LOWER(SUBSTITUTE(SUBSTITUTE($K18," ",""),CHAR(160),""))),Verpleegkundigen!$B$2:$B$100)+IF($K18<>"",1,0)) -> 36 | G18: =IF(AND(C18<>"",D18<>"",C18>D18),"+" & TEXT(C18-D18,"0"),"") | H18: 31 aanhouden, Sarina 9.30-14.30u | I18: =IF($J18="",4,LEN($J18)-LEN(SUBSTITUTE($J18,",",""))+1) -> 5 | J18: henriette, suzan, sarina, irma, yvonne | K18: henriette
A19: 46042 | B19: di | C19: 22 | D19: 31 | E19: =IF(F19>D19,1,IF(F19=D19,0,-1)) -> 1 | F19: =IF(AND($J19="",$K19=""),"",SUMPRODUCT(--ISNUMBER(SEARCH(","&Verpleegkundigen!$C$2:$C$100&",",","&LOWER(SUBSTITUTE(SUBSTITUTE($J19," ",""),CHAR(160),""))&","))*(Verpleegkundigen!$C$2:$C$100<>LOWER(SUBSTITUTE(SUBSTITUTE($K19," ",""),CHAR(160),""))),Verpleegkundigen!$B$2:$B$100)+IF($K19<>"",1,0)) -> 41 | G19: =IF(AND(C19<>"",D19<>"",C19>D19),"+" & TEXT(C19-D19,"0"),"") | H19: 31 aanhouden / BELEIDSDAG / 4 aanprikmomenten, wel gewoon 31 pt ovv Senna | I19: =IF($J19="",4,LEN($J19)-LEN(SUBSTITUTE($J19,",",""))+1) -> 5 | J19: henriette, sanne, joyce, irma, yvonne | K19: sanne
A20: 46043 | B20: wo | C20: 28 | D20: 31 | E20: =IF(F20>D20,1,IF(F20=D20,0,-1)) -> 1 | F20: =IF(AND($J20="",$K20=""),"",SUMPRODUCT(--ISNUMBER(SEARCH(","&Verpleegkundigen!$C$2:$C$100&",",","&LOWER(SUBSTITUTE(SUBSTITUTE($J20," ",""),CHAR(160),""))&","))*(Verpleegkundigen!$C$2:$C$100<>LOWER(SUBSTITUTE(SUBSTITUTE($K20," ",""),CHAR(160),""))),Verpleegkundigen!$B$2:$B$100)+IF($K20<>"",1,0)) -> 37 | G20: =IF(AND(C20<>"",D20<>"",C20>D20),"+" & TEXT(C20-D20,"0"),"") | H20: 31 aanhouden | I20: =IF($J20="",4,LEN($J20)-LEN(SUBSTITUTE($J20,",",""))+1) -> 5 | J20: henriette, carla, sanne, lisa, yvonne | K20: carla
A21: 46044 | B21: do | C21: 26 | D21: 31 | E21: =IF(F21>D21,1,IF(F21=D21,0,-1)) -> 0 | F21: =IF(AND($J21="",$K21=""),"",SUMPRODUCT(--ISNUMBER(SEARCH(","&Verpleegkundigen!$C$2:$C$100&",",","&LOWER(SUBSTITUTE(SUBSTITUTE($J21," ",""),CHAR(160),""))&","))*(Verpleegkundigen!$C$2:$C$100<>LOWER(SUBSTITUTE(SUBSTITUTE($K21," ",""),CHAR(160),""))),Verpleegkundigen!$B$2:$B$100)+IF($K21<>"",1,0)) -> 31 | G21: =IF(AND(C21<>"",D21<>"",C21>D21),"+" & TEXT(C21-D21,"0"),"") | H21: 31 aanhouden | I21: =IF($J21="",4,LEN($J21)-LEN(SUBSTITUTE($J21,",",""))+1) -> 4 | J21: henriette, suzan, irma, merel | K21: suzan | L21: 15dec: Sarina 9.30-13u, nader afstemmen hoeveel patiënten
A22: 46045 | B22: vr | C22: 27 | D22: 31 | E22: =IF(F22>D22,1,IF(F22=D22,0,-1)) -> 1 | F22: =IF(AND($J22="",$K22=""),"",SUMPRODUCT(--ISNUMBER(SEARCH(","&Verpleegkundigen!$C$2:$C$100&",",","&LOWER(SUBSTITUTE(SUBSTITUTE($J22," ",""),CHAR(160),""))&","))*(Verpleegkundigen!$C$2:$C$100<>LOWER(SUBSTITUTE(SUBSTITUTE($K22," ",""),CHAR(160),""))),Verpleegkundigen!$B$2:$B$100)+IF($K22<>"",1,0)) -> 37 | G22: =IF(AND(C22<>"",D22<>"",C22>D22),"+" & TEXT(C22-D22,"0"),"") | H22: 31 aanhouden | I22: =IF($J22="",4,LEN($J22)-LEN(SUBSTITUTE($J22,",",""))+1) -> 5 | J22: carla, emmy, sanne, joyce, lisa | K22: joyce
A23: Week 5 | F23: =IF(AND($J23="",$K23=""),"",SUMPRODUCT(--ISNUMBER(SEARCH(","&Verpleegkundigen!$C$2:$C$100&",",","&LOWER(SUBSTITUTE(SUBSTITUTE($J23," ",""),CHAR(160),""))&","))*(Verpleegkundigen!$C$2:$C$100<>LOWER(SUBSTITUTE(SUBSTITUTE($K23," ",""),CHAR(160),""))),Verpleegkundigen!$B$2:$B$100)+IF($K23<>"",1,0))
A24: 46048 | B24: ma | C24: 24 | D24: 31 | E24: =IF(F24>D24,1,IF(F24=D24,0,-1)) -> 1 | F24: =IF(AND($J24="",$K24=""),"",SUMPRODUCT(--ISNUMBER(SEARCH(","&Verpleegkundigen!$C$2:$C$100&",",","&LOWER(SUBSTITUTE(SUBSTITUTE($J24," ",""),CHAR(160),""))&","))*(Verpleegkundigen!$C$2:$C$100<>LOWER(SUBSTITUTE(SUBSTITUTE($K24," ",""),CHAR(160),""))),Verpleegkundigen!$B$2:$B$100)+IF($K24<>"",1,0)) -> 41 | G24: =IF(AND(C24<>"",D24<>"",C24>D24),"+" & TEXT(C24-D24,"0"),"") | H24: 31 aanhouden | I24: =IF($J24="",4,LEN($J24)-LEN(SUBSTITUTE($J24,",",""))+1) -> 5 | J24: henriette, suzan, irma, merel, yvonne | K24: merel | L24: 15dec: Sarina 9.30-13,30u, nader afstemmen hoeveel patiënten
A25: 46049 | B25: di | C25: 29 | D25: 31 | E25: =IF(F25>D25,1,IF(F25=D25,0,-1)) -> 0 | F25: =IF(AND($J25="",$K25=""),"",SUMPRODUCT(--ISNUMBER(SEARCH(","&Verpleegkundigen!$C$2:$C$100&",",","&LOWER(SUBSTITUTE(SUBSTITUTE($J25," ",""),CHAR(160),""))&","))*(Verpleegkundigen!$C$2:$C$100<>LOWER(SUBSTITUTE(SUBSTITUTE($K25," ",""),CHAR(160),""))),Verpleegkundigen!$B$2:$B$100)+IF($K25<>"",1,0)) -> 31 | G25: =IF(AND(C25<>"",D25<>"",C25>D25),"+" & TEXT(C25-D25,"0"),"") | H25: 31 aanhouden | I25: =IF($J25="",4,LEN($J25)-LEN(SUBSTITUTE($J25,",",""))+1) -> 4 | J25: carla, sanne, irma, yvonne | K25: carla
A26: 46050 | B26: wo | C26: 27 | D26: 31 | E26: =IF(F26>D26,1,IF(F26=D26,0,-1)) -> -1 | F26: =IF(AND($J26="",$K26=""),"",SUMPRODUCT(--ISNUMBER(SEARCH(","&Verpleegkundigen!$C$2:$C$100&",",","&LOWER(SUBSTITUTE(SUBSTITUTE($J26," ",""),CHAR(160),""))&","))*(Verpleegkundigen!$C$2:$C$100<>LOWER(SUBSTITUTE(SUBSTITUTE($K26," ",""),CHAR(160),""))),Verpleegkundigen!$B$2:$B$100)+IF($K26<>"",1,0)) -> 27 | G26: =IF(AND(C26<>"",D26<>"",C26>D26),"+" & TEXT(C26-D26,"0"),"") | H26: 31 aanhouden | I26: =IF($J26="",4,LEN($J26)-LEN(SUBSTITUTE($J26,",",""))+1) -> 4 | J26: sanne, joyce, lisa, merel | K26: sanne
A27: 46051 | B27: do | C27: 22 | D27: 31 | E27: =IF(F27>D27,1,IF(F27=D27,0,-1)) -> 1 | F27: =IF(AND($J27="",$K27=""),"",SUMPRODUCT(--ISNUMBER(SEARCH(","&Verpleegkundigen!$C$2:$C$100&",",","&LOWER(SUBSTITUTE(SUBSTITUTE($J27," ",""),CHAR(160),""))&","))*(Verpleegkundigen!$C$2:$C$100<>LOWER(SUBSTITUTE(SUBSTITUTE($K27," ",""),CHAR(160),""))),Verpleegkundigen!$B$2:$B$100)+IF($K27<>"",1,0)) -> 36 | G27: =IF(AND(C27<>"",D27<>"",C27>D27),"+" & TEXT(C27-D27,"0"),"") | H27: 31 aanhouden, Sarina 9.30-14.30u | I27: =IF($J27="",4,LEN($J27)-LEN(SUBSTITUTE($J27,",",""))+1) -> 5 | J27: henriette, suzan, sarina, irma, yvonne | K27: suzan
A28: 46052 | B28: vr | C28: 30 | D28: 31 | E28: =IF(F28>D28,1,IF(F28=D28,0,-1)) -> 1 | F28: =IF(AND($J28="",$K28=""),"",SUMPRODUCT(--ISNUMBER(SEARCH(","&Verpleegkundigen!$C$2:$C$100&",",","&LOWER(SUBSTITUTE(SUBSTITUTE($J28," ",""),CHAR(160),""))&","))*(Verpleegkundigen!$C$2:$C$100<>LOWER(SUBSTITUTE(SUBSTITUTE($K28," ",""),CHAR(160),""))),Verpleegkundigen!$B$2:$B$100)+IF($K28<>"",1,0)) -> 37 | G28: =IF(AND(C28<>"",D28<>"",C28>D28),"+" & TEXT(C28-D28,"0"),"") | H28: 31 aanhouden | I28: =IF($J28="",4,LEN($J28)-LEN(SUBSTITUTE($J28,",",""))+1) -> 5 | J28: carla, sanne, joyce, irma, lisa | K28: carla
C31: formule -> | D31: =IF(AND($J31="",$K31=""),"",SUMPRODUCT(--ISNUMBER(SEARCH(","&Verpleegkundigen!$C$2:$C$100&",",","&LOWER(SUBSTITUTE(SUBSTITUTE($J31," ",""),CHAR(160),""))&","))*(Verpleegkundigen!$C$2:$C$100<>LOWER(SUBSTITUTE(SUBSTITUTE($K31," ",""),CHAR(160),""))),Verpleegkundigen!$B$2:$B$100)+IF($K31<>"",1,0))

Sheet feb'26
A1: Datum | B1: Weekdag | C1: Aantal patiënten | D1: Max aantal patiënten afgesproken | F1: Max Capaciteit | G1: Overschrijding | H1: Opmerking | I1: Aantal vpk | J1: Naam verpleegkundige | K1: Dagco (naam) | L1: Opmerkingen Senna
A2: Week 6 | F2: =IF(AND($J2="",$K2=""),"",SUMPRODUCT(--ISNUMBER(SEARCH(","&Verpleegkundigen!$C$2:$C$100&",",","&LOWER(SUBSTITUTE(SUBSTITUTE($J2," ",""),CHAR(160),""))&","))*(Verpleegkundigen!$C$2:$C$100<>LOWER(SUBSTITUTE(SUBSTITUTE($K2," ",""),CHAR(160),""))),Verpleegkundigen!$B$2:$B$100)+IF($K2<>"",1,0))
A3: 46055 | B3: ma | C3: 28 | D3: 31 | E3: =IF(F3>D3,1,IF(F3=D3,0,-1)) -> 1 | F3: =IF(AND($J3="",$K3=""),"",SUMPRODUCT(--ISNUMBER(SEARCH(","&Verpleegkundigen!$C$2:$C$100&",",","&LOWER(SUBSTITUTE(SUBSTITUTE($J3," ",""),CHAR(160),""))&","))*(Verpleegkundigen!$C$2:$C$100<>LOWER(SUBSTITUTE(SUBSTITUTE($K3," ",""),CHAR(160),""))),Verpleegkundigen!$B$2:$B$100)+IF($K3<>"",1,0)) -> 36 | G3: =IF(AND(C3<>"",D3<>"",C3>D3),"+" & TEXT(C3-D3,"0"),"") | H3: Sarina 9.30-14.30u | I3: =IF($J3="",5,LEN($J3)-LEN(SUBSTITUTE($J3,",",""))+1) -> 5 | J3: Henriette, carla, suzan, merel, sarina | K3: henriette
A4: 46056 | B4: di | C4: 22 | D4: =IF(AND($J4="",$K4=""),"",SUMPRODUCT(--ISNUMBER(SEARCH(","&Verpleegkundigen!$C$2:$C$100&",",","&LOWER(SUBSTITUTE(SUBSTITUTE($J4," ",""),CHAR(160),""))&","))*(Verpleegkundigen!$C$2:$C$100<>LOWER(SUBSTITUTE(SUBSTITUTE($K4," ",""),CHAR(160),""))),Verpleegkundigen!$B$2:$B$100)+IF($K4<>"",1,0)) -> 31 | E4: =IF(F4>D4,1,IF(F4=D4,0,-1)) -> 0 | F4: =IF(AND($J4="",$K4=""),"",SUMPRODUCT(--ISNUMBER(SEARCH(","&Verpleegkundigen!$C$2:$C$100&",",","&LOWER(SUBSTITUTE(SUBSTITUTE($J4," ",""),CHAR(160),""))&","))*(Verpleegkundigen!$C$2:$C$100<>LOWER(SUBSTITUTE(SUBSTITUTE($K4," ",""),CHAR(160),""))),Verpleegkundigen!$B$2:$B$100)+IF($K4<>"",1,0)) -> 31 | G4: =IF(AND(C4<>"",D4<>"",C4>D4),"+" & TEXT(C4-D4,"0"),"") | I4: =IF($J4="",5,LEN($J4)-LEN(SUBSTITUTE($J4,",",""))+1) -> 4 | J4: henriette, sanne, irma, yvonne | K4: sanne
A5: 46057 | B5: wo | C5: 26 | D5: 31 | E5: =IF(F5>D5,1,IF(F5=D5,0,-1)) -> 1 | F5: =IF(AND($J5="",$K5=""),"",SUMPRODUCT(--ISNUMBER(SEARCH(","&Verpleegkundigen!$C$2:$C$100&",",","&LOWER(SUBSTITUTE(SUBSTITUTE($J5," ",""),CHAR(160),""))&","))*(Verpleegkundigen!$C$2:$C$100<>LOWER(SUBSTITUTE(SUBSTITUTE($K5," ",""),CHAR(160),""))),Verpleegkundigen!$B$2:$B$100)+IF($K5<>"",1,0)) -> 41 | G5: =IF(AND(C5<>"",D5<>"",C5>D5),"+" & TEXT(C5-D5,"0"),"") | I5: =IF($J5="",5,LEN($J5)-LEN(SUBSTITUTE($J5,",",""))+1) -> 5 | J5: sanne, joyce, irma, lisa, yvonne | K5: lisa
A6: 46058 | B6: do | C6: 21 | D6: =IF(AND($J6="",$K6=""),"",SUMPRODUCT(--ISNUMBER(SEARCH(","&Verpleegkundigen!$C$2:$C$100&",",","&LOWER(SUBSTITUTE(SUBSTITUTE($J6," ",""),CHAR(160),""))&","))*(Verpleegkundigen!$C$2:$C$100<>LOWER(SUBSTITUTE(SUBSTITUTE($K6," ",""),CHAR(160),""))),Verpleegkundigen!$B$2:$B$100)+IF($K6<>"",1,0)) -> 31 | E6: =IF(F6>D6,1,IF(F6=D6,0,-1)) -> 0 | F6: =IF(AND($J6="",$K6=""),"",SUMPRODUCT(--ISNUMBER(SEARCH(","&Verpleegkundigen!$C$2:$C$100&",",","&LOWER(SUBSTITUTE(SUBSTITUTE($J6," ",""),CHAR(160),""))&","))*(Verpleegkundigen!$C$2:$C$100<>LOWER(SUBSTITUTE(SUBSTITUTE($K6," ",""),CHAR(160),""))),Verpleegkundigen!$B$2:$B$100)+IF($K6<>"",1,0)) -> 31 | G6: =IF(AND(C6<>"",D6<>"",C6>D6),"+" & TEXT(C6-D6,"0"),"") | I6: =IF($J6="",5,LEN($J6)-LEN(SUBSTITUTE($J6,",",""))+1) -> 4 | J6: henriette, suzan, merel, yvonne | K6: merel | L6: 15dec: Sarina 9.30-14u, nader afstemmen hoeveel patiënten
A7: 46059 | B7: vr | C7: 21 | D7: 31 | E7: =IF(F7>D7,1,IF(F7=D7,0,-1)) -> 1 | F7: =IF(AND($J7="",$K7=""),"",SUMPRODUCT(--ISNUMBER(SEARCH(","&Verpleegkundigen!$C$2:$C$100&",",","&LOWER(SUBSTITUTE(SUBSTITUTE($J7," ",""),CHAR(160),""))&","))*(Verpleegkundigen!$C$2:$C$100<>LOWER(SUBSTITUTE(SUBSTITUTE($K7," ",""),CHAR(160),""))),Verpleegkundigen!$B$2:$B$100)+IF($K7<>"",1,0)) -> 41 | G7: =IF(AND(C7<>"",D7<>"",C7>D7),"+" & TEXT(C7-D7,"0"),"") | I7: =IF($J7="",5,LEN($J7)-LEN(SUBSTITUTE($J7,",",""))+1) -> 5 | J7: carla, emmy, sanne, joyce, irma | K7: joyce
A8: Week 7 | F8: =IF(AND($J8="",$K8=""),"",SUMPRODUCT(--ISNUMBER(SEARCH(","&Verpleegkundigen!$C$2:$C$100&",",","&LOWER(SUBSTITUTE(SUBSTITUTE($J8," ",""),CHAR(160),""))&","))*(Verpleegkundigen!$C$2:$C$100<>LOWER(SUBSTITUTE(SUBSTITUTE($K8," ",""),CHAR(160),""))),Verpleegkundigen!$B$2:$B$100)+IF($K8<>"",1,0))
A9: 46062 | B9: ma | C9: 20 | D9: 31 | E9: =IF(F9>D9,1,IF(F9=D9,0,-1)) -> 0 | F9: =IF(AND($J9="",$K9=""),"",SUMPRODUCT(--ISNUMBER(SEARCH(","&Verpleegkundigen!$C$2:$C$100&",",","&LOWER(SUBSTITUTE(SUBSTITUTE($J9," ",""),CHAR(160),""))&","))*(Verpleegkundigen!$C$2:$C$100<>LOWER(SUBSTITUTE(SUBSTITUTE($K9," ",""),CHAR(160),""))),Verpleegkundigen!$B$2:$B$100)+IF($K9<>"",1,0)) -> 31 | G9: =IF(AND(C9<>"",D9<>"",C9>D9),"+" & TEXT(C9-D9,"0"),"") | I9: =IF($J9="",5,LEN($J9)-LEN(SUBSTITUTE($J9,",",""))+1) -> 4 | J9: henriette, suzan, merel, yvonne | K9: merel | L9: 15dec: Sarina 9.30-14,30u, nader afstemmen hoeveel patiënten
A10: 46063 | B10: di | C10: 20 | D10: 31 | E10: =IF(F10>D10,1,IF(F10=D10,0,-1)) -> 1 | F10: =IF(AND($J10="",$K10=""),"",SUMPRODUCT(--ISNUMBER(SEARCH(","&Verpleegkundigen!$C$2:$C$100&",",","&LOWER(SUBSTITUTE(SUBSTITUTE($J10," ",""),CHAR(160),""))&","))*(Verpleegkundigen!$C$2:$C$100<>LOWER(SUBSTITUTE(SUBSTITUTE($K10," ",""),CHAR(160),""))),Verpleegkundigen!$B$2:$B$100)+IF($K10<>"",1,0)) -> 51 | G10: =IF(AND(C10<>"",D10<>"",C10>D10),"+" & TEXT(C10-D10,"0"),"") | I10: =IF($J10="",5,LEN($J10)-LEN(SUBSTITUTE($J10,",",""))+1) -> 6 | J10: henriette, emmy, merel, suzan, yvonne, joyce | K10: suzan
A11: 46064 | B11: wo | C11: 17 | D11: 31 | E11: =IF(F11>D11,1,IF(F11=D11,0,-1)) -> 1 | F11: =IF(AND($J11="",$K11=""),"",SUMPRODUCT(--ISNUMBER(SEARCH(","&Verpleegkundigen!$C$2:$C$100&",",","&LOWER(SUBSTITUTE(SUBSTITUTE($J11," ",""),CHAR(160),""))&","))*(Verpleegkundigen!$C$2:$C$100<>LOWER(SUBSTITUTE(SUBSTITUTE($K11," ",""),CHAR(160),""))),Verpleegkundigen!$B$2:$B$100)+IF($K11<>"",1,0)) -> 47 | G11: =IF(AND(C11<>"",D11<>"",C11>D11),"+" & TEXT(C11-D11,"0"),"") | I11: =IF($J11="",5,LEN($J11)-LEN(SUBSTITUTE($J11,",",""))+1) -> 6 | J11: emmy, suzan, sanne, irma, lisa, yvonne | K11: emmy
A12: 46065 | B12: do | C12: 17 | D12: 31 | E12: =IF(F12>D12,1,IF(F12=D12,0,-1)) -> -1 | F12: =IF(AND($J12="",$K12=""),"",SUMPRODUCT(--ISNUMBER(SEARCH(","&Verpleegkundigen!$C$2:$C$100&",",","&LOWER(SUBSTITUTE(SUBSTITUTE($J12," ",""),CHAR(160),""))&","))*(Verpleegkundigen!$C$2:$C$100<>LOWER(SUBSTITUTE(SUBSTITUTE($K12," ",""),CHAR(160),""))),Verpleegkundigen!$B$2:$B$100)+IF($K12<>"",1,0)) -> 26 | G12: =IF(AND(C12<>"",D12<>"",C12>D12),"+" & TEXT(C12-D12,"0"),"") | H12: Sarina 9.30-14.30u | I12: =IF($J12="",5,LEN($J12)-LEN(SUBSTITUTE($J12,",",""))+1) -> 4 | J12: henriette, sarina, irma, merel | K12: henriette
A13: 46066 | B13: vr | C13: 22 | D13: 31 | E13: =IF(F13>D13,1,IF(F13=D13,0,-1)) -> 1 | F13: =IF(AND($J13="",$K13=""),"",SUMPRODUCT(--ISNUMBER(SEARCH(","&Verpleegkundigen!$C$2:$C$100&",",","&LOWER(SUBSTITUTE(SUBSTITUTE($J13," ",""),CHAR(160),""))&","))*(Verpleegkundigen!$C$2:$C$100<>LOWER(SUBSTITUTE(SUBSTITUTE($K13," ",""),CHAR(160),""))),Verpleegkundigen!$B$2:$B$100)+IF($K13<>"",1,0)) -> 41 | G13: =IF(AND(C13<>"",D13<>"",C13>D13),"+" & TEXT(C13-D13,"0"),"") | I13: =IF($J13="",5,LEN($J13)-LEN(SUBSTITUTE($J13,",",""))+1) -> 5 | J13: carla, emmy, joyce, irma, lisa | K13: lisa
A14: Week 8 | F14: =IF(AND($J14="",$K14=""),"",SUMPRODUCT(--ISNUMBER(SEARCH(","&Verpleegkundigen!$C$2:$C$100&",",","&LOWER(SUBSTITUTE(SUBSTITUTE($J14," ",""),CHAR(160),""))&","))*(Verpleegkundigen!$C$2:$C$100<>LOWER(SUBSTITUTE(SUBSTITUTE($K14," ",""),CHAR(160),""))),Verpleegkundigen!$B$2:$B$100)+IF($K14<>"",1,0))
A15: 46069 | B15: ma | C15: 20 | D15: 31 | E15: =IF(F15>D15,1,IF(F15=D15,0,-1)) -> 0 | F15: =IF(AND($J15="",$K15=""),"",SUMPRODUCT(--ISNUMBER(SEARCH(","&Verpleegkundigen!$C$2:$C$100&",",","&LOWER(SUBSTITUTE(SUBSTITUTE($J15," ",""),CHAR(160),""))&","))*(Verpleegkundigen!$C$2:$C$100<>LOWER(SUBSTITUTE(SUBSTITUTE($K15," ",""),CHAR(160),""))),Verpleegkundigen!$B$2:$B$100)+IF($K15<>"",1,0)) -> 31 | G15: =IF(AND(C15<>"",D15<>"",C15>D15),"+" & TEXT(C15-D15,"0"),"") | I15: =IF($J15="",5,LEN($J15)-LEN(SUBSTITUTE($J15,",",""))+1) -> 4 | J15: henriette, suzan, joyce, merel | K15: joyce
A16: 46070 | B16: di | C16: 16 | D16: 31 | E16: =IF(F16>D16,1,IF(F16=D16,0,-1)) -> 0 | F16: =IF(AND($J16="",$K16=""),"",SUMPRODUCT(--ISNUMBER(SEARCH(","&Verpleegkundigen!$C$2:$C$100&",",","&LOWER(SUBSTITUTE(SUBSTITUTE($J16," ",""),CHAR(160),""))&","))*(Verpleegkundigen!$C$2:$C$100<>LOWER(SUBSTITUTE(SUBSTITUTE($K16," ",""),CHAR(160),""))),Verpleegkundigen!$B$2:$B$100)+IF($K16<>"",1,0)) -> 31 | G16: =IF(AND(C16<>"",D16<>"",C16>D16),"+" & TEXT(C16-D16,"0"),"") | I16: =IF($J16="",5,LEN($J16)-LEN(SUBSTITUTE($J16,",",""))+1) -> 4 | J16: henriette, carla, merel, yvonne | K16: merel
A17: 46071 | B17: wo | C17: 22 | D17: 31 | E17: =IF(F17>D17,1,IF(F17=D17,0,-1)) -> 1 | F17: =IF(AND($J17="",$K17=""),"",SUMPRODUCT(--ISNUMBER(SEARCH(","&Verpleegkundigen!$C$2:$C$100&",",","&LOWER(SUBSTITUTE(SUBSTITUTE($J17," ",""),CHAR(160),""))&","))*(Verpleegkundigen!$C$2:$C$100<>LOWER(SUBSTITUTE(SUBSTITUTE($K17," ",""),CHAR(160),""))),Verpleegkundigen!$B$2:$B$100)+IF($K17<>"",1,0)) -> 37 | G17: =IF(AND(C17<>"",D17<>"",C17>D17),"+" & TEXT(C17-D17,"0"),"") | I17: =IF($J17="",5,LEN($J17)-LEN(SUBSTITUTE($J17,",",""))+1) -> 5 | J17: henriete, suzan, irma, lisa, yvonne | K17: henriette
A18: 46072 | B18: do | C18: 24 | D18: 31 | E18: =IF(F18>D18,1,IF(F18=D18,0,-1)) -> 0 | F18: =IF(AND($J18="",$K18=""),"",SUMPRODUCT(--ISNUMBER(SEARCH(","&Verpleegkundigen!$C$2:$C$100&",",","&LOWER(SUBSTITUTE(SUBSTITUTE($J18," ",""),CHAR(160),""))&","))*(Verpleegkundigen!$C$2:$C$100<>LOWER(SUBSTITUTE(SUBSTITUTE($K18," ",""),CHAR(160),""))),Verpleegkundigen!$B$2:$B$100)+IF($K18<>"",1,0)) -> 31 | G18: =IF(AND(C18<>"",D18<>"",C18>D18),"+" & TEXT(C18-D18,"0"),"") | I18: =IF($J18="",5,LEN($J18)-LEN(SUBSTITUTE($J18,",",""))+1) -> 4 | J18: henriette,emmy, suzan, irma | K18: emmy
A19: 46073 | B19: vr | C19: 16 | D19: 31 | E19: =IF(F19>D19,1,IF(F19=D19,0,-1)) -> 0 | F19: =IF(AND($J19="",$K19=""),"",SUMPRODUCT(--ISNUMBER(SEARCH(","&Verpleegkundigen!$C$2:$C$100&",",","&LOWER(SUBSTITUTE(SUBSTITUTE($J19," ",""),CHAR(160),""))&","))*(Verpleegkundigen!$C$2:$C$100<>LOWER(SUBSTITUTE(SUBSTITUTE($K19," ",""),CHAR(160),""))),Verpleegkundigen!$B$2:$B$100)+IF($K19<>"",1,0)) -> 31 | G19: =IF(AND(C19<>"",D19<>"",C19>D19),"+" & TEXT(C19-D19,"0"),"") | I19: =IF($J19="",5,LEN($J19)-LEN(SUBSTITUTE($J19,",",""))+1) -> 4 | J19: carla, emmy, joyce, lisa | K19: lisa
A20: Week 9 | F20: =IF(AND($J20="",$K20=""),"",SUMPRODUCT(--ISNUMBER(SEARCH(","&Verpleegkundigen!$C$2:$C$100&",",","&LOWER(SUBSTITUTE(SUBSTITUTE($J20," ",""),CHAR(160),""))&","))*(Verpleegkundigen!$C$2:$C$100<>LOWER(SUBSTITUTE(SUBSTITUTE($K20," ",""),CHAR(160),""))),Verpleegkundigen!$B$2:$B$100)+IF($K20<>"",1,0))
A21: 46076 | B21: ma | C21: 16 | D21: 31 | E21: =IF(F21>D21,1,IF(F21=D21,0,-1)) -> 0 | F21: =IF(AND($J21="",$K21=""),"",SUMPRODUCT(--ISNUMBER(SEARCH(","&Verpleegkundigen!$C$2:$C$100&",",","&LOWER(SUBSTITUTE(SUBSTITUTE($J21," ",""),CHAR(160),""))&","))*(Verpleegkundigen!$C$2:$C$100<>LOWER(SUBSTITUTE(SUBSTITUTE($K21," ",""),CHAR(160),""))),Verpleegkundigen!$B$2:$B$100)+IF($K21<>"",1,0)) -> 31 | G21: =IF(AND(C21<>"",D21<>"",C21>D21),"+" & TEXT(C21-D21,"0"),"") | I21: =IF($J21="",5,LEN($J21)-LEN(SUBSTITUTE($J21,",",""))+1) -> 4 | J21: henriette, suzan, irma, merel | K21: suzan
A22: 46077 | B22: di | C22: 18 | D22: 31 | E22: =IF(F22>D22,1,IF(F22=D22,0,-1)) -> 1 | F22: =IF(AND($J22="",$K22=""),"",SUMPRODUCT(--ISNUMBER(SEARCH(","&Verpleegkundigen!$C$2:$C$100&",",","&LOWER(SUBSTITUTE(SUBSTITUTE($J22," ",""),CHAR(160),""))&","))*(Verpleegkundigen!$C$2:$C$100<>LOWER(SUBSTITUTE(SUBSTITUTE($K22," ",""),CHAR(160),""))),Verpleegkundigen!$B$2:$B$100)+IF($K22<>"",1,0)) -> 51 | G22: =IF(AND(C22<>"",D22<>"",C22>D22),"+" & TEXT(C22-D22,"0"),"") | I22: =IF($J22="",5,LEN($J22)-LEN(SUBSTITUTE($J22,",",""))+1) -> 6 | J22: henriette, carla, emmy, irma, merel, yvonne | K22: carla
A23: 46078 | B23: wo | C23: 17 | D23: 31 | E23: =IF(F23>D23,1,IF(F23=D23,0,-1)) -> 1 | F23: =IF(AND($J23="",$K23=""),"",SUMPRODUCT(--ISNUMBER(SEARCH(","&Verpleegkundigen!$C$2:$C$100&",",","&LOWER(SUBSTITUTE(SUBSTITUTE($J23," ",""),CHAR(160),""))&","))*(Verpleegkundigen!$C$2:$C$100<>LOWER(SUBSTITUTE(SUBSTITUTE($K23," ",""),CHAR(160),""))),Verpleegkundigen!$B$2:$B$100)+IF($K23<>"",1,0)) -> 37 | G23: =IF(AND(C23<>"",D23<>"",C23>D23),"+" & TEXT(C23-D23,"0"),"") | I23: =IF($J23="",5,LEN($J23)-LEN(SUBSTITUTE($J23,",",""))+1) -> 5 | J23: emmy, sanne, joyce, lisa, yvonne | K23: sanne
A24: 46079 | B24: do | C24: 21 | D24: 31 | E24: =IF(F24>D24,1,IF(F24=D24,0,-1)) -> 0 | F24: =IF(AND($J24="",$K24=""),"",SUMPRODUCT(--ISNUMBER(SEARCH(","&Verpleegkundigen!$C$2:$C$100&",",","&LOWER(SUBSTITUTE(SUBSTITUTE($J24," ",""),CHAR(160),""))&","))*(Verpleegkundigen!$C$2:$C$100<>LOWER(SUBSTITUTE(SUBSTITUTE($K24," ",""),CHAR(160),""))),Verpleegkundigen!$B$2:$B$100)+IF($K24<>"",1,0)) -> 31 | G24: =IF(AND(C24<>"",D24<>"",C24>D24),"+" & TEXT(C24-D24,"0"),"") | I24: =IF($J24="",5,LEN($J24)-LEN(SUBSTITUTE($J24,",",""))+1) -> 4 | J24: henriette, suzan, irma, yvonne | K24: henriette
A25: 46080 | B25: vr | C25: 10 | D25: 31 | E25: =IF(F25>D25,1,IF(F25=D25,0,-1)) -> 1 | F25: =IF(AND($J25="",$K25=""),"",SUMPRODUCT(--ISNUMBER(SEARCH(","&Verpleegkundigen!$C$2:$C$100&",",","&LOWER(SUBSTITUTE(SUBSTITUTE($J25," ",""),CHAR(160),""))&","))*(Verpleegkundigen!$C$2:$C$100<>LOWER(SUBSTITUTE(SUBSTITUTE($K25," ",""),CHAR(160),""))),Verpleegkundigen!$B$2:$B$100)+IF($K25<>"",1,0)) -> 41 | G25: =IF(AND(C25<>"",D25<>"",C25>D25),"+" & TEXT(C25-D25,"0"),"") | I25: =IF($J25="",5,LEN($J25)-LEN(SUBSTITUTE($J25,",",""))+1) -> 5 | J25: emmy, sanne, joyce, irma, lisa | K25: lisa

Sheet mrt'26
A1: Datum | B1: Weekdag | C1: Aantal patiënten | D1: Max aantal patiënten afgesproken | F1: Max Capaciteit | G1: Overschrijding | H1: Opmerking | I1: Aantal vpk | J1: Naam verpleegkundige | K1: Dagco (naam) | L1: Opmerkingen Senna
A2: Week 10
A3: 46083 | B3: ma | C3: 4 | D3: =IF(AND($J3="",$K3=""),"",SUMPRODUCT(--ISNUMBER(SEARCH(","&Verpleegkundigen!$C$2:$C$100&",",","&LOWER(SUBSTITUTE(SUBSTITUTE($J3," ",""),CHAR(160),""))&","))*(Verpleegkundigen!$C$2:$C$100<>LOWER(SUBSTITUTE(SUBSTITUTE($K3," ",""),CHAR(160),""))),Verpleegkundigen!$B$2:$B$100)+IF($K3<>"",1,0)) | E3: =IF(F3>D3,1,IF(F3=D3,0,-1)) -> 0 | F3: =IF(AND($J3="",$K3=""),"",SUMPRODUCT(--ISNUMBER(SEARCH(","&Verpleegkundigen!$C$2:$C$100&",",","&LOWER(SUBSTITUTE(SUBSTITUTE($J3," ",""),CHAR(160),""))&","))*(Verpleegkundigen!$C$2:$C$100<>LOWER(SUBSTITUTE(SUBSTITUTE($K3," ",""),CHAR(160),""))),Verpleegkundigen!$B$2:$B$100)+IF($K3<>"",1,0)) | G3: =IF(AND(C3<>"",D3<>"",C3>D3),"+" & TEXT(C3-D3,"0"),"") | I3: =IF($J3="",5,LEN($J3)-LEN(SUBSTITUTE($J3,",",""))+1) -> 5
